2018-11-14 17:11:34 [django.template:925] [DEBUG] - Exception while resolving variable 'errmsg' in template 'login.html'.
Traceback (most recent call last):
  File "/root/python36env/lib/python3.6/site-packages/django/template/base.py", line 882, in _resolve_lookup
    current = current[bit]
  File "/root/python36env/lib/python3.6/site-packages/django/template/context.py", line 87, in __getitem__
    raise KeyError(key)
KeyError: 'errmsg'

During handling of the above exception, another exception occurred:

Traceback (most recent call last):
  File "/root/python36env/lib/python3.6/site-packages/django/template/base.py", line 888, in _resolve_lookup
    if isinstance(current, BaseContext) and getattr(type(current), bit):
AttributeError: type object 'RequestContext' has no attribute 'errmsg'

During handling of the above exception, another exception occurred:

Traceback (most recent call last):
  File "/root/python36env/lib/python3.6/site-packages/django/template/base.py", line 896, in _resolve_lookup
    current = current[int(bit)]
ValueError: invalid literal for int() with base 10: 'errmsg'

During handling of the above exception, another exception occurred:

Traceback (most recent call last):
  File "/root/python36env/lib/python3.6/site-packages/django/template/base.py", line 903, in _resolve_lookup
    (bit, current))  # missing attribute
django.template.base.VariableDoesNotExist: Failed lookup for key [errmsg] in "[{'True': True, 'False': False, 'None': None}, {'csrf_token': <SimpleLazyObject: <function csrf.<locals>._get_val at 0x7f9da716a7b8>>, 'request': <WSGIRequest: GET '/'>, 'user': <SimpleLazyObject: <function AuthenticationMiddleware.process_request.<locals>.<lambda> at 0x7f9da8fe9ae8>>, 'perms': <django.contrib.auth.context_processors.PermWrapper object at 0x7f9da71775c0>, 'messages': <django.contrib.messages.storage.fallback.FallbackStorage object at 0x7f9da714bc18>, 'DEFAULT_MESSAGE_LEVELS': {'DEBUG': 10, 'INFO': 20, 'SUCCESS': 25, 'WARNING': 30, 'ERROR': 40}}, {}]"
2018-11-14 17:11:34 [django.server:124] [INFO] - "GET / HTTP/1.1" 200 2151
2018-11-14 17:11:34 [django.server:124] [WARNING] - "GET /static/fonts/glyphicons-halflings-regular.woff2 HTTP/1.1" 404 1738
2018-11-14 17:11:34 [django.server:124] [WARNING] - "GET /static/fonts/glyphicons-halflings-regular.woff HTTP/1.1" 404 1735
2018-11-14 17:11:35 [django.template:925] [DEBUG] - Exception while resolving variable 'name' in template 'unknown'.
Traceback (most recent call last):
  File "/root/python36env/lib/python3.6/site-packages/django/core/handlers/exception.py", line 41, in inner
    response = get_response(request)
  File "/root/python36env/lib/python3.6/site-packages/django/core/handlers/base.py", line 172, in _get_response
    resolver_match = resolver.resolve(request.path_info)
  File "/root/python36env/lib/python3.6/site-packages/django/urls/resolvers.py", line 392, in resolve
    raise Resolver404({'tried': tried, 'path': new_path})
django.urls.exceptions.Resolver404: {'tried': [[<RegexURLPattern None ^$>], [<RegexURLPattern None ^home/>], [<RegexURLResolver <module 'account.urls' from '/WorkSpace/Study/Reboot/12/webapp/account/urls.py'> (None:None) ^account/>], [<RegexURLResolver <module 'assets.urls' from '/WorkSpace/Study/Reboot/12/webapp/assets/urls.py'> (None:None) ^assets/>], [<RegexURLResolver <module 'users.urls' from '/WorkSpace/Study/Reboot/12/webapp/users/urls.py'> (None:None) ^user/>]], 'path': 'favicon.ico'}

During handling of the above exception, another exception occurred:

Traceback (most recent call last):
  File "/root/python36env/lib/python3.6/site-packages/django/template/base.py", line 882, in _resolve_lookup
    current = current[bit]
TypeError: 'RegexURLResolver' object is not subscriptable

During handling of the above exception, another exception occurred:

Traceback (most recent call last):
  File "/root/python36env/lib/python3.6/site-packages/django/template/base.py", line 890, in _resolve_lookup
    current = getattr(current, bit)
AttributeError: 'RegexURLResolver' object has no attribute 'name'

During handling of the above exception, another exception occurred:

Traceback (most recent call last):
  File "/root/python36env/lib/python3.6/site-packages/django/template/base.py", line 896, in _resolve_lookup
    current = current[int(bit)]
ValueError: invalid literal for int() with base 10: 'name'

During handling of the above exception, another exception occurred:

Traceback (most recent call last):
  File "/root/python36env/lib/python3.6/site-packages/django/template/base.py", line 903, in _resolve_lookup
    (bit, current))  # missing attribute
django.template.base.VariableDoesNotExist: Failed lookup for key [name] in "<RegexURLResolver <module 'account.urls' from '/WorkSpace/Study/Reboot/12/webapp/account/urls.py'> (None:None) ^account/>"
2018-11-14 17:11:35 [django.template:925] [DEBUG] - Exception while resolving variable 'name' in template 'unknown'.
Traceback (most recent call last):
  File "/root/python36env/lib/python3.6/site-packages/django/core/handlers/exception.py", line 41, in inner
    response = get_response(request)
  File "/root/python36env/lib/python3.6/site-packages/django/core/handlers/base.py", line 172, in _get_response
    resolver_match = resolver.resolve(request.path_info)
  File "/root/python36env/lib/python3.6/site-packages/django/urls/resolvers.py", line 392, in resolve
    raise Resolver404({'tried': tried, 'path': new_path})
django.urls.exceptions.Resolver404: {'tried': [[<RegexURLPattern None ^$>], [<RegexURLPattern None ^home/>], [<RegexURLResolver <module 'account.urls' from '/WorkSpace/Study/Reboot/12/webapp/account/urls.py'> (None:None) ^account/>], [<RegexURLResolver <module 'assets.urls' from '/WorkSpace/Study/Reboot/12/webapp/assets/urls.py'> (None:None) ^assets/>], [<RegexURLResolver <module 'users.urls' from '/WorkSpace/Study/Reboot/12/webapp/users/urls.py'> (None:None) ^user/>]], 'path': 'favicon.ico'}

During handling of the above exception, another exception occurred:

Traceback (most recent call last):
  File "/root/python36env/lib/python3.6/site-packages/django/template/base.py", line 882, in _resolve_lookup
    current = current[bit]
TypeError: 'RegexURLResolver' object is not subscriptable

During handling of the above exception, another exception occurred:

Traceback (most recent call last):
  File "/root/python36env/lib/python3.6/site-packages/django/template/base.py", line 890, in _resolve_lookup
    current = getattr(current, bit)
AttributeError: 'RegexURLResolver' object has no attribute 'name'

During handling of the above exception, another exception occurred:

Traceback (most recent call last):
  File "/root/python36env/lib/python3.6/site-packages/django/template/base.py", line 896, in _resolve_lookup
    current = current[int(bit)]
ValueError: invalid literal for int() with base 10: 'name'

During handling of the above exception, another exception occurred:

Traceback (most recent call last):
  File "/root/python36env/lib/python3.6/site-packages/django/template/base.py", line 903, in _resolve_lookup
    (bit, current))  # missing attribute
django.template.base.VariableDoesNotExist: Failed lookup for key [name] in "<RegexURLResolver <module 'assets.urls' from '/WorkSpace/Study/Reboot/12/webapp/assets/urls.py'> (None:None) ^assets/>"
2018-11-14 17:11:35 [django.template:925] [DEBUG] - Exception while resolving variable 'name' in template 'unknown'.
Traceback (most recent call last):
  File "/root/python36env/lib/python3.6/site-packages/django/core/handlers/exception.py", line 41, in inner
    response = get_response(request)
  File "/root/python36env/lib/python3.6/site-packages/django/core/handlers/base.py", line 172, in _get_response
    resolver_match = resolver.resolve(request.path_info)
  File "/root/python36env/lib/python3.6/site-packages/django/urls/resolvers.py", line 392, in resolve
    raise Resolver404({'tried': tried, 'path': new_path})
django.urls.exceptions.Resolver404: {'tried': [[<RegexURLPattern None ^$>], [<RegexURLPattern None ^home/>], [<RegexURLResolver <module 'account.urls' from '/WorkSpace/Study/Reboot/12/webapp/account/urls.py'> (None:None) ^account/>], [<RegexURLResolver <module 'assets.urls' from '/WorkSpace/Study/Reboot/12/webapp/assets/urls.py'> (None:None) ^assets/>], [<RegexURLResolver <module 'users.urls' from '/WorkSpace/Study/Reboot/12/webapp/users/urls.py'> (None:None) ^user/>]], 'path': 'favicon.ico'}

During handling of the above exception, another exception occurred:

Traceback (most recent call last):
  File "/root/python36env/lib/python3.6/site-packages/django/template/base.py", line 882, in _resolve_lookup
    current = current[bit]
TypeError: 'RegexURLResolver' object is not subscriptable

During handling of the above exception, another exception occurred:

Traceback (most recent call last):
  File "/root/python36env/lib/python3.6/site-packages/django/template/base.py", line 890, in _resolve_lookup
    current = getattr(current, bit)
AttributeError: 'RegexURLResolver' object has no attribute 'name'

During handling of the above exception, another exception occurred:

Traceback (most recent call last):
  File "/root/python36env/lib/python3.6/site-packages/django/template/base.py", line 896, in _resolve_lookup
    current = current[int(bit)]
ValueError: invalid literal for int() with base 10: 'name'

During handling of the above exception, another exception occurred:

Traceback (most recent call last):
  File "/root/python36env/lib/python3.6/site-packages/django/template/base.py", line 903, in _resolve_lookup
    (bit, current))  # missing attribute
django.template.base.VariableDoesNotExist: Failed lookup for key [name] in "<RegexURLResolver <module 'users.urls' from '/WorkSpace/Study/Reboot/12/webapp/users/urls.py'> (None:None) ^user/>"
2018-11-14 17:11:35 [django.server:124] [WARNING] - "GET /favicon.ico HTTP/1.1" 404 2391
2018-11-14 17:11:39 [django.server:124] [INFO] - "POST /account/login/ HTTP/1.1" 302 0
2018-11-14 17:11:39 [django.server:124] [INFO] - "GET /home/ HTTP/1.1" 200 6414
2018-11-14 17:11:42 [django.server:124] [INFO] - "GET /user/list/ HTTP/1.1" 200 34144
2018-11-14 17:12:17 [django.server:124] [INFO] - "GET /user/detail/?pk=16 HTTP/1.1" 200 71
2018-11-14 17:12:22 [django.server:124] [INFO] - "PUT /user/edit/16/ HTTP/1.1" 200 32
2018-11-14 17:12:22 [django.server:124] [INFO] - "GET /user/list/ HTTP/1.1" 200 34144
2018-11-14 17:12:28 [django.server:124] [INFO] - "GET /user/detail/?pk=16 HTTP/1.1" 200 71
2018-11-14 17:12:29 [django.server:124] [INFO] - "PUT /user/edit/16/ HTTP/1.1" 200 32
2018-11-14 17:12:30 [django.server:124] [INFO] - "GET /user/list/ HTTP/1.1" 200 34144
2018-11-14 17:12:50 [django.server:124] [INFO] - "GET /user/detail/?pk=16 HTTP/1.1" 200 71
2018-11-14 17:18:00 [django.server:124] [WARNING] - "GET /static/fonts/glyphicons-halflings-regular.woff2 HTTP/1.1" 404 1738
2018-11-14 17:18:42 [django.server:124] [ERROR] - "GET /user/list/?search_value=zhou HTTP/1.1" 500 71103
2018-11-14 17:19:01 [django.server:124] [ERROR] - "GET /user/list/ HTTP/1.1" 500 71065
2018-11-14 17:19:05 [django.server:124] [ERROR] - "GET /user/list/ HTTP/1.1" 500 70908
2018-11-14 17:19:38 [django.server:124] [INFO] - "GET /user/list/ HTTP/1.1" 200 34144
2018-11-14 17:19:54 [django.server:124] [ERROR] - "GET /user/list/?search_value=zhou HTTP/1.1" 500 71080
2018-11-14 17:20:33 [django.server:124] [INFO] - "GET /user/list/?search_value=zhou HTTP/1.1" 200 22197
2018-11-14 17:21:07 [django.server:124] [INFO] - "GET /user/list/ HTTP/1.1" 200 34144
2018-11-14 17:21:11 [django.server:124] [INFO] - "GET /user/list/?search_value= HTTP/1.1" 200 34144
2018-11-14 17:21:15 [django.server:124] [INFO] - "GET /user/list/?search_value=zhou HTTP/1.1" 200 22197
2018-11-14 17:22:06 [django.server:124] [INFO] - "GET /user/list/ HTTP/1.1" 200 34144
2018-11-14 17:22:22 [django.server:124] [INFO] - "GET /user/list/?search_value=zhou HTTP/1.1" 200 22197
2018-11-14 17:22:48 [django.server:124] [INFO] - "GET /user/list/ HTTP/1.1" 200 34144
2018-11-14 17:22:50 [django.server:124] [INFO] - "GET /user/detail/?pk=9 HTTP/1.1" 200 68
2018-11-14 17:23:03 [django.server:124] [INFO] - "GET /user/detail/?pk=7 HTTP/1.1" 200 68
2018-11-14 17:23:17 [django.server:124] [INFO] - "GET /user/detail/?pk=16 HTTP/1.1" 200 71
2018-11-14 17:39:45 [django.server:124] [INFO] - "GET /user/detail/?pk=9 HTTP/1.1" 200 68
2018-11-14 17:39:59 [django.server:124] [INFO] - "GET /assets/list/ HTTP/1.1" 200 36408
2018-11-14 17:40:04 [django.server:124] [INFO] - "GET /assets/detail/?pk=31 HTTP/1.1" 200 244
2018-11-14 17:41:15 [django.server:124] [INFO] - "GET /assets/list/ HTTP/1.1" 200 36408
2018-11-14 17:41:30 [django.server:124] [INFO] - "GET /assets/list/ HTTP/1.1" 200 36408
2018-11-14 17:41:31 [django.server:124] [INFO] - "GET /assets/detail/?pk=31 HTTP/1.1" 200 244
2018-11-14 17:41:33 [django.server:124] [INFO] - "GET /assets/detail/?pk=47 HTTP/1.1" 200 245
2018-11-15 10:15:55 [django.template:925] [DEBUG] - Exception while resolving variable 'errmsg' in template 'login.html'.
Traceback (most recent call last):
  File "/root/python36env/lib/python3.6/site-packages/django/template/base.py", line 882, in _resolve_lookup
    current = current[bit]
  File "/root/python36env/lib/python3.6/site-packages/django/template/context.py", line 87, in __getitem__
    raise KeyError(key)
KeyError: 'errmsg'

During handling of the above exception, another exception occurred:

Traceback (most recent call last):
  File "/root/python36env/lib/python3.6/site-packages/django/template/base.py", line 888, in _resolve_lookup
    if isinstance(current, BaseContext) and getattr(type(current), bit):
AttributeError: type object 'RequestContext' has no attribute 'errmsg'

During handling of the above exception, another exception occurred:

Traceback (most recent call last):
  File "/root/python36env/lib/python3.6/site-packages/django/template/base.py", line 896, in _resolve_lookup
    current = current[int(bit)]
ValueError: invalid literal for int() with base 10: 'errmsg'

During handling of the above exception, another exception occurred:

Traceback (most recent call last):
  File "/root/python36env/lib/python3.6/site-packages/django/template/base.py", line 903, in _resolve_lookup
    (bit, current))  # missing attribute
django.template.base.VariableDoesNotExist: Failed lookup for key [errmsg] in "[{'True': True, 'False': False, 'None': None}, {'csrf_token': <SimpleLazyObject: <function csrf.<locals>._get_val at 0x7f515c0ff7b8>>, 'request': <WSGIRequest: GET '/'>, 'user': <SimpleLazyObject: <function AuthenticationMiddleware.process_request.<locals>.<lambda> at 0x7f515dc31ae8>>, 'perms': <django.contrib.auth.context_processors.PermWrapper object at 0x7f515c10c518>, 'messages': <django.contrib.messages.storage.fallback.FallbackStorage object at 0x7f515c0e0b70>, 'DEFAULT_MESSAGE_LEVELS': {'DEBUG': 10, 'INFO': 20, 'SUCCESS': 25, 'WARNING': 30, 'ERROR': 40}}, {}]"
2018-11-15 10:15:55 [django.server:124] [INFO] - "GET / HTTP/1.1" 200 2151
2018-11-15 10:15:55 [django.server:124] [INFO] - "GET /static/css/bootstrap.min.css HTTP/1.1" 304 0
2018-11-15 10:15:55 [django.server:124] [INFO] - "GET /static/css/font-awesome.min.css HTTP/1.1" 304 0
2018-11-15 10:15:56 [django.server:124] [INFO] - "GET /static/css/ionicons.min.css HTTP/1.1" 304 0
2018-11-15 10:15:56 [django.server:124] [INFO] - "GET /static/css/AdminLTE.min.css HTTP/1.1" 304 0
2018-11-15 10:15:56 [django.server:124] [INFO] - "GET /static/css/blue.css HTTP/1.1" 304 0
2018-11-15 10:15:56 [django.server:124] [WARNING] - "GET /static/fonts/glyphicons-halflings-regular.woff2 HTTP/1.1" 404 1738
2018-11-15 10:15:56 [django.server:124] [WARNING] - "GET /static/fonts/glyphicons-halflings-regular.woff HTTP/1.1" 404 1735
2018-11-15 10:15:56 [django.server:124] [INFO] - "GET /static/fonts/glyphicons-halflings-regular.ttf HTTP/1.1" 304 0
2018-11-15 10:15:56 [django.template:925] [DEBUG] - Exception while resolving variable 'name' in template 'unknown'.
Traceback (most recent call last):
  File "/root/python36env/lib/python3.6/site-packages/django/core/handlers/exception.py", line 41, in inner
    response = get_response(request)
  File "/root/python36env/lib/python3.6/site-packages/django/core/handlers/base.py", line 172, in _get_response
    resolver_match = resolver.resolve(request.path_info)
  File "/root/python36env/lib/python3.6/site-packages/django/urls/resolvers.py", line 392, in resolve
    raise Resolver404({'tried': tried, 'path': new_path})
django.urls.exceptions.Resolver404: {'tried': [[<RegexURLPattern None ^$>], [<RegexURLPattern None ^home/>], [<RegexURLResolver <module 'account.urls' from '/WorkSpace/Study/Reboot/12/webapp/account/urls.py'> (None:None) ^account/>], [<RegexURLResolver <module 'assets.urls' from '/WorkSpace/Study/Reboot/12/webapp/assets/urls.py'> (None:None) ^assets/>], [<RegexURLResolver <module 'users.urls' from '/WorkSpace/Study/Reboot/12/webapp/users/urls.py'> (None:None) ^user/>]], 'path': 'favicon.ico'}

During handling of the above exception, another exception occurred:

Traceback (most recent call last):
  File "/root/python36env/lib/python3.6/site-packages/django/template/base.py", line 882, in _resolve_lookup
    current = current[bit]
TypeError: 'RegexURLResolver' object is not subscriptable

During handling of the above exception, another exception occurred:

Traceback (most recent call last):
  File "/root/python36env/lib/python3.6/site-packages/django/template/base.py", line 890, in _resolve_lookup
    current = getattr(current, bit)
AttributeError: 'RegexURLResolver' object has no attribute 'name'

During handling of the above exception, another exception occurred:

Traceback (most recent call last):
  File "/root/python36env/lib/python3.6/site-packages/django/template/base.py", line 896, in _resolve_lookup
    current = current[int(bit)]
ValueError: invalid literal for int() with base 10: 'name'

During handling of the above exception, another exception occurred:

Traceback (most recent call last):
  File "/root/python36env/lib/python3.6/site-packages/django/template/base.py", line 903, in _resolve_lookup
    (bit, current))  # missing attribute
django.template.base.VariableDoesNotExist: Failed lookup for key [name] in "<RegexURLResolver <module 'account.urls' from '/WorkSpace/Study/Reboot/12/webapp/account/urls.py'> (None:None) ^account/>"
2018-11-15 10:15:56 [django.template:925] [DEBUG] - Exception while resolving variable 'name' in template 'unknown'.
Traceback (most recent call last):
  File "/root/python36env/lib/python3.6/site-packages/django/core/handlers/exception.py", line 41, in inner
    response = get_response(request)
  File "/root/python36env/lib/python3.6/site-packages/django/core/handlers/base.py", line 172, in _get_response
    resolver_match = resolver.resolve(request.path_info)
  File "/root/python36env/lib/python3.6/site-packages/django/urls/resolvers.py", line 392, in resolve
    raise Resolver404({'tried': tried, 'path': new_path})
django.urls.exceptions.Resolver404: {'tried': [[<RegexURLPattern None ^$>], [<RegexURLPattern None ^home/>], [<RegexURLResolver <module 'account.urls' from '/WorkSpace/Study/Reboot/12/webapp/account/urls.py'> (None:None) ^account/>], [<RegexURLResolver <module 'assets.urls' from '/WorkSpace/Study/Reboot/12/webapp/assets/urls.py'> (None:None) ^assets/>], [<RegexURLResolver <module 'users.urls' from '/WorkSpace/Study/Reboot/12/webapp/users/urls.py'> (None:None) ^user/>]], 'path': 'favicon.ico'}

During handling of the above exception, another exception occurred:

Traceback (most recent call last):
  File "/root/python36env/lib/python3.6/site-packages/django/template/base.py", line 882, in _resolve_lookup
    current = current[bit]
TypeError: 'RegexURLResolver' object is not subscriptable

During handling of the above exception, another exception occurred:

Traceback (most recent call last):
  File "/root/python36env/lib/python3.6/site-packages/django/template/base.py", line 890, in _resolve_lookup
    current = getattr(current, bit)
AttributeError: 'RegexURLResolver' object has no attribute 'name'

During handling of the above exception, another exception occurred:

Traceback (most recent call last):
  File "/root/python36env/lib/python3.6/site-packages/django/template/base.py", line 896, in _resolve_lookup
    current = current[int(bit)]
ValueError: invalid literal for int() with base 10: 'name'

During handling of the above exception, another exception occurred:

Traceback (most recent call last):
  File "/root/python36env/lib/python3.6/site-packages/django/template/base.py", line 903, in _resolve_lookup
    (bit, current))  # missing attribute
django.template.base.VariableDoesNotExist: Failed lookup for key [name] in "<RegexURLResolver <module 'assets.urls' from '/WorkSpace/Study/Reboot/12/webapp/assets/urls.py'> (None:None) ^assets/>"
2018-11-15 10:15:56 [django.template:925] [DEBUG] - Exception while resolving variable 'name' in template 'unknown'.
Traceback (most recent call last):
  File "/root/python36env/lib/python3.6/site-packages/django/core/handlers/exception.py", line 41, in inner
    response = get_response(request)
  File "/root/python36env/lib/python3.6/site-packages/django/core/handlers/base.py", line 172, in _get_response
    resolver_match = resolver.resolve(request.path_info)
  File "/root/python36env/lib/python3.6/site-packages/django/urls/resolvers.py", line 392, in resolve
    raise Resolver404({'tried': tried, 'path': new_path})
django.urls.exceptions.Resolver404: {'tried': [[<RegexURLPattern None ^$>], [<RegexURLPattern None ^home/>], [<RegexURLResolver <module 'account.urls' from '/WorkSpace/Study/Reboot/12/webapp/account/urls.py'> (None:None) ^account/>], [<RegexURLResolver <module 'assets.urls' from '/WorkSpace/Study/Reboot/12/webapp/assets/urls.py'> (None:None) ^assets/>], [<RegexURLResolver <module 'users.urls' from '/WorkSpace/Study/Reboot/12/webapp/users/urls.py'> (None:None) ^user/>]], 'path': 'favicon.ico'}

During handling of the above exception, another exception occurred:

Traceback (most recent call last):
  File "/root/python36env/lib/python3.6/site-packages/django/template/base.py", line 882, in _resolve_lookup
    current = current[bit]
TypeError: 'RegexURLResolver' object is not subscriptable

During handling of the above exception, another exception occurred:

Traceback (most recent call last):
  File "/root/python36env/lib/python3.6/site-packages/django/template/base.py", line 890, in _resolve_lookup
    current = getattr(current, bit)
AttributeError: 'RegexURLResolver' object has no attribute 'name'

During handling of the above exception, another exception occurred:

Traceback (most recent call last):
  File "/root/python36env/lib/python3.6/site-packages/django/template/base.py", line 896, in _resolve_lookup
    current = current[int(bit)]
ValueError: invalid literal for int() with base 10: 'name'

During handling of the above exception, another exception occurred:

Traceback (most recent call last):
  File "/root/python36env/lib/python3.6/site-packages/django/template/base.py", line 903, in _resolve_lookup
    (bit, current))  # missing attribute
django.template.base.VariableDoesNotExist: Failed lookup for key [name] in "<RegexURLResolver <module 'users.urls' from '/WorkSpace/Study/Reboot/12/webapp/users/urls.py'> (None:None) ^user/>"
2018-11-15 10:15:56 [django.server:124] [WARNING] - "GET /favicon.ico HTTP/1.1" 404 2391
2018-11-15 10:16:06 [django.server:124] [INFO] - "POST /account/login/ HTTP/1.1" 302 0
2018-11-15 10:16:06 [django.server:124] [INFO] - "GET /home/ HTTP/1.1" 200 6414
2018-11-15 10:16:06 [django.server:124] [INFO] - "GET /static/css/_all-skins.min.css HTTP/1.1" 304 0
2018-11-15 10:16:06 [django.server:124] [INFO] - "GET /static/css/morris.css HTTP/1.1" 304 0
2018-11-15 10:16:06 [django.server:124] [INFO] - "GET /static/css/jquery-jvectormap.css HTTP/1.1" 304 0
2018-11-15 10:16:06 [django.server:124] [INFO] - "GET /static/css/bootstrap-datepicker.min.css HTTP/1.1" 304 0
2018-11-15 10:16:06 [django.server:124] [INFO] - "GET /static/css/daterangepicker.css HTTP/1.1" 304 0
2018-11-15 10:16:06 [django.server:124] [INFO] - "GET /static/css/bootstrap3-wysihtml5.min.css HTTP/1.1" 304 0
2018-11-15 10:16:06 [django.server:124] [INFO] - "GET /static/js/bootstrap.min.js HTTP/1.1" 304 0
2018-11-15 10:16:06 [django.server:124] [INFO] - "GET /static/css/sweetalert.css HTTP/1.1" 304 0
2018-11-15 10:16:06 [django.server:124] [INFO] - "GET /static/js/jquery.min.js HTTP/1.1" 304 0
2018-11-15 10:16:06 [django.server:124] [INFO] - "GET /static/js/adminlte.min.js HTTP/1.1" 304 0
2018-11-15 10:16:06 [django.server:124] [INFO] - "GET /static/js/sweetalert.min.js HTTP/1.1" 304 0
2018-11-15 10:16:06 [django.server:124] [INFO] - "GET /static/img/user2-160x160.jpg HTTP/1.1" 304 0
2018-11-15 10:16:08 [django.server:124] [INFO] - "GET /assets/list/ HTTP/1.1" 200 36408
2018-11-15 10:16:12 [django.server:124] [INFO] - "GET /user/list/ HTTP/1.1" 200 34144
2018-11-15 10:21:18 [django.server:124] [INFO] - "GET /user/list/ HTTP/1.1" 200 34144
2018-11-15 10:21:18 [django.server:124] [INFO] - "GET /user/list/ HTTP/1.1" 200 34144
2018-11-15 10:21:19 [django.server:124] [INFO] - "GET /user/list/ HTTP/1.1" 200 34144
2018-11-15 10:21:19 [django.server:124] [INFO] - "GET /user/list/ HTTP/1.1" 200 34144
2018-11-15 11111111 
2018-11-15 22222222 
2018-11-15 33333333 
2018-11-15 44444444 
2018-11-15 11111115 
2018-11-15 11111116 
2018-11-15 11111117 
2018-11-15 11111118 
2018-11-15 11111119 
2018-11-15 11111128 
2018-11-15 11111138 
2018-11-15 11111148 
2018-11-15 11111158 
2018-11-15 11111168 
2018-11-15 11111178 
2018-11-15 11111288 
2018-11-15 11111388 
2018-11-15 11111488
2018-11-15 11111588 
2018-11-15 11111688 
2018-11-15 11111788 
2018-11-15 11111888 
2018-11-15 11111988 
2018-11-15 11111088 
2018-11-15 11111188 
