2018-11-16 18:55:25 [django.template:925] [DEBUG] - Exception while resolving variable 'name' in template 'unknown'.
Traceback (most recent call last):
  File "/Library/Frameworks/Python.framework/Versions/3.6/lib/python3.6/site-packages/django/core/handlers/exception.py", line 41, in inner
    response = get_response(request)
  File "/Library/Frameworks/Python.framework/Versions/3.6/lib/python3.6/site-packages/django/core/handlers/base.py", line 172, in _get_response
    resolver_match = resolver.resolve(request.path_info)
  File "/Library/Frameworks/Python.framework/Versions/3.6/lib/python3.6/site-packages/django/urls/resolvers.py", line 392, in resolve
    raise Resolver404({'tried': tried, 'path': new_path})
django.urls.exceptions.Resolver404: {'tried': [[<RegexURLResolver <RegexURLPattern list> (admin:admin) ^admin/>], [<RegexURLPattern None ^account/login>], [<RegexURLPattern None ^account/logout>], [<RegexURLPattern None ^user/home>], [<RegexURLPattern None ^user/add>], [<RegexURLPattern None ^user/list>], [<RegexURLPattern None ^user/detail>], [<RegexURLPattern None ^user/delete/(?P<id>[0-9]+)/$>], [<RegexURLPattern None ^user/update/(?P<id>[0-9]+)/$>], [<RegexURLPattern None ^user/export>]], 'path': ''}

During handling of the above exception, another exception occurred:

Traceback (most recent call last):
  File "/Library/Frameworks/Python.framework/Versions/3.6/lib/python3.6/site-packages/django/template/base.py", line 882, in _resolve_lookup
    current = current[bit]
TypeError: 'RegexURLResolver' object is not subscriptable

During handling of the above exception, another exception occurred:

Traceback (most recent call last):
  File "/Library/Frameworks/Python.framework/Versions/3.6/lib/python3.6/site-packages/django/template/base.py", line 890, in _resolve_lookup
    current = getattr(current, bit)
AttributeError: 'RegexURLResolver' object has no attribute 'name'

During handling of the above exception, another exception occurred:

Traceback (most recent call last):
  File "/Library/Frameworks/Python.framework/Versions/3.6/lib/python3.6/site-packages/django/template/base.py", line 896, in _resolve_lookup
    current = current[int(bit)]
ValueError: invalid literal for int() with base 10: 'name'

During handling of the above exception, another exception occurred:

Traceback (most recent call last):
  File "/Library/Frameworks/Python.framework/Versions/3.6/lib/python3.6/site-packages/django/template/base.py", line 903, in _resolve_lookup
    (bit, current))  # missing attribute
django.template.base.VariableDoesNotExist: Failed lookup for key [name] in '<RegexURLResolver <RegexURLPattern list> (admin:admin) ^admin/>'
2018-11-16 18:55:25 [django.server:124] [WARNING] - "GET / HTTP/1.1" 404 2962
2018-11-16 18:55:25 [django.template:925] [DEBUG] - Exception while resolving variable 'name' in template 'unknown'.
Traceback (most recent call last):
  File "/Library/Frameworks/Python.framework/Versions/3.6/lib/python3.6/site-packages/django/core/handlers/exception.py", line 41, in inner
    response = get_response(request)
  File "/Library/Frameworks/Python.framework/Versions/3.6/lib/python3.6/site-packages/django/core/handlers/base.py", line 172, in _get_response
    resolver_match = resolver.resolve(request.path_info)
  File "/Library/Frameworks/Python.framework/Versions/3.6/lib/python3.6/site-packages/django/urls/resolvers.py", line 392, in resolve
    raise Resolver404({'tried': tried, 'path': new_path})
django.urls.exceptions.Resolver404: {'tried': [[<RegexURLResolver <RegexURLPattern list> (admin:admin) ^admin/>], [<RegexURLPattern None ^account/login>], [<RegexURLPattern None ^account/logout>], [<RegexURLPattern None ^user/home>], [<RegexURLPattern None ^user/add>], [<RegexURLPattern None ^user/list>], [<RegexURLPattern None ^user/detail>], [<RegexURLPattern None ^user/delete/(?P<id>[0-9]+)/$>], [<RegexURLPattern None ^user/update/(?P<id>[0-9]+)/$>], [<RegexURLPattern None ^user/export>]], 'path': 'favicon.ico'}

During handling of the above exception, another exception occurred:

Traceback (most recent call last):
  File "/Library/Frameworks/Python.framework/Versions/3.6/lib/python3.6/site-packages/django/template/base.py", line 882, in _resolve_lookup
    current = current[bit]
TypeError: 'RegexURLResolver' object is not subscriptable

During handling of the above exception, another exception occurred:

Traceback (most recent call last):
  File "/Library/Frameworks/Python.framework/Versions/3.6/lib/python3.6/site-packages/django/template/base.py", line 890, in _resolve_lookup
    current = getattr(current, bit)
AttributeError: 'RegexURLResolver' object has no attribute 'name'

During handling of the above exception, another exception occurred:

Traceback (most recent call last):
  File "/Library/Frameworks/Python.framework/Versions/3.6/lib/python3.6/site-packages/django/template/base.py", line 896, in _resolve_lookup
    current = current[int(bit)]
ValueError: invalid literal for int() with base 10: 'name'

During handling of the above exception, another exception occurred:

Traceback (most recent call last):
  File "/Library/Frameworks/Python.framework/Versions/3.6/lib/python3.6/site-packages/django/template/base.py", line 903, in _resolve_lookup
    (bit, current))  # missing attribute
django.template.base.VariableDoesNotExist: Failed lookup for key [name] in '<RegexURLResolver <RegexURLPattern list> (admin:admin) ^admin/>'
2018-11-16 18:55:25 [django.server:124] [WARNING] - "GET /favicon.ico HTTP/1.1" 404 3013
2018-11-16 18:55:28 [django.template:925] [DEBUG] - Exception while resolving variable 'is_popup' in template 'admin/index.html'.
Traceback (most recent call last):
  File "/Library/Frameworks/Python.framework/Versions/3.6/lib/python3.6/site-packages/django/template/base.py", line 882, in _resolve_lookup
    current = current[bit]
  File "/Library/Frameworks/Python.framework/Versions/3.6/lib/python3.6/site-packages/django/template/context.py", line 87, in __getitem__
    raise KeyError(key)
KeyError: 'is_popup'

During handling of the above exception, another exception occurred:

Traceback (most recent call last):
  File "/Library/Frameworks/Python.framework/Versions/3.6/lib/python3.6/site-packages/django/template/base.py", line 888, in _resolve_lookup
    if isinstance(current, BaseContext) and getattr(type(current), bit):
AttributeError: type object 'RequestContext' has no attribute 'is_popup'

During handling of the above exception, another exception occurred:

Traceback (most recent call last):
  File "/Library/Frameworks/Python.framework/Versions/3.6/lib/python3.6/site-packages/django/template/base.py", line 896, in _resolve_lookup
    current = current[int(bit)]
ValueError: invalid literal for int() with base 10: 'is_popup'

During handling of the above exception, another exception occurred:

Traceback (most recent call last):
  File "/Library/Frameworks/Python.framework/Versions/3.6/lib/python3.6/site-packages/django/template/base.py", line 903, in _resolve_lookup
    (bit, current))  # missing attribute
django.template.base.VariableDoesNotExist: Failed lookup for key [is_popup] in "[{'True': True, 'False': False, 'None': None}, {'csrf_token': <SimpleLazyObject: <function csrf.<locals>._get_val at 0x10ef24378>>, 'request': <WSGIRequest: GET '/admin/'>, 'user': <SimpleLazyObject: <User: root>>, 'perms': <django.contrib.auth.context_processors.PermWrapper object at 0x10ef861d0>, 'messages': <django.contrib.messages.storage.fallback.FallbackStorage object at 0x10eee7438>, 'DEFAULT_MESSAGE_LEVELS': {'DEBUG': 10, 'INFO': 20, 'SUCCESS': 25, 'WARNING': 30, 'ERROR': 40}}, {}, {'site_title': 'Django 站点管理员', 'site_header': 'Django 管理', 'site_url': '/', 'has_permission': True, 'available_apps': [{'name': 'User', 'app_label': 'user', 'app_url': '/admin/user/', 'has_module_perms': True, 'models': [{'name': 'Userss', 'object_name': 'Users', 'perms': {'add': True, 'change': True, 'delete': True}, 'admin_url': '/admin/user/users/', 'add_url': '/admin/user/users/add/'}]}, {'name': '认证和授权', 'app_label': 'auth', 'app_url': '/admin/auth/', 'has_module_perms': True, 'models': [{'name': '用户', 'object_name': 'User', 'perms': {'add': True, 'change': True, 'delete': True}, 'admin_url': '/admin/auth/user/', 'add_url': '/admin/auth/user/add/'}, {'name': '组', 'object_name': 'Group', 'perms': {'add': True, 'change': True, 'delete': True}, 'admin_url': '/admin/auth/group/', 'add_url': '/admin/auth/group/add/'}]}], 'title': '站点管理', 'app_list': [{'name': 'User', 'app_label': 'user', 'app_url': '/admin/user/', 'has_module_perms': True, 'models': [{'name': 'Userss', 'object_name': 'Users', 'perms': {'add': True, 'change': True, 'delete': True}, 'admin_url': '/admin/user/users/', 'add_url': '/admin/user/users/add/'}]}, {'name': '认证和授权', 'app_label': 'auth', 'app_url': '/admin/auth/', 'has_module_perms': True, 'models': [{'name': '用户', 'object_name': 'User', 'perms': {'add': True, 'change': True, 'delete': True}, 'admin_url': '/admin/auth/user/', 'add_url': '/admin/auth/user/add/'}, {'name': '组', 'object_name': 'Group', 'perms': {'add': True, 'change': True, 'delete': True}, 'admin_url': '/admin/auth/group/', 'add_url': '/admin/auth/group/add/'}]}], 'LANGUAGE_CODE': 'zh-hans', 'LANGUAGE_BIDI': False}]"
2018-11-16 18:55:28 [django.template:925] [DEBUG] - Exception while resolving variable 'is_popup' in template 'admin/index.html'.
Traceback (most recent call last):
  File "/Library/Frameworks/Python.framework/Versions/3.6/lib/python3.6/site-packages/django/template/base.py", line 882, in _resolve_lookup
    current = current[bit]
  File "/Library/Frameworks/Python.framework/Versions/3.6/lib/python3.6/site-packages/django/template/context.py", line 87, in __getitem__
    raise KeyError(key)
KeyError: 'is_popup'

During handling of the above exception, another exception occurred:

Traceback (most recent call last):
  File "/Library/Frameworks/Python.framework/Versions/3.6/lib/python3.6/site-packages/django/template/base.py", line 888, in _resolve_lookup
    if isinstance(current, BaseContext) and getattr(type(current), bit):
AttributeError: type object 'RequestContext' has no attribute 'is_popup'

During handling of the above exception, another exception occurred:

Traceback (most recent call last):
  File "/Library/Frameworks/Python.framework/Versions/3.6/lib/python3.6/site-packages/django/template/base.py", line 896, in _resolve_lookup
    current = current[int(bit)]
ValueError: invalid literal for int() with base 10: 'is_popup'

During handling of the above exception, another exception occurred:

Traceback (most recent call last):
  File "/Library/Frameworks/Python.framework/Versions/3.6/lib/python3.6/site-packages/django/template/base.py", line 903, in _resolve_lookup
    (bit, current))  # missing attribute
django.template.base.VariableDoesNotExist: Failed lookup for key [is_popup] in "[{'True': True, 'False': False, 'None': None}, {'csrf_token': <SimpleLazyObject: <function csrf.<locals>._get_val at 0x10ef24378>>, 'request': <WSGIRequest: GET '/admin/'>, 'user': <SimpleLazyObject: <User: root>>, 'perms': <django.contrib.auth.context_processors.PermWrapper object at 0x10ef861d0>, 'messages': <django.contrib.messages.storage.fallback.FallbackStorage object at 0x10eee7438>, 'DEFAULT_MESSAGE_LEVELS': {'DEBUG': 10, 'INFO': 20, 'SUCCESS': 25, 'WARNING': 30, 'ERROR': 40}}, {}, {'site_title': 'Django 站点管理员', 'site_header': 'Django 管理', 'site_url': '/', 'has_permission': True, 'available_apps': [{'name': 'User', 'app_label': 'user', 'app_url': '/admin/user/', 'has_module_perms': True, 'models': [{'name': 'Userss', 'object_name': 'Users', 'perms': {'add': True, 'change': True, 'delete': True}, 'admin_url': '/admin/user/users/', 'add_url': '/admin/user/users/add/'}]}, {'name': '认证和授权', 'app_label': 'auth', 'app_url': '/admin/auth/', 'has_module_perms': True, 'models': [{'name': '用户', 'object_name': 'User', 'perms': {'add': True, 'change': True, 'delete': True}, 'admin_url': '/admin/auth/user/', 'add_url': '/admin/auth/user/add/'}, {'name': '组', 'object_name': 'Group', 'perms': {'add': True, 'change': True, 'delete': True}, 'admin_url': '/admin/auth/group/', 'add_url': '/admin/auth/group/add/'}]}], 'title': '站点管理', 'app_list': [{'name': 'User', 'app_label': 'user', 'app_url': '/admin/user/', 'has_module_perms': True, 'models': [{'name': 'Userss', 'object_name': 'Users', 'perms': {'add': True, 'change': True, 'delete': True}, 'admin_url': '/admin/user/users/', 'add_url': '/admin/user/users/add/'}]}, {'name': '认证和授权', 'app_label': 'auth', 'app_url': '/admin/auth/', 'has_module_perms': True, 'models': [{'name': '用户', 'object_name': 'User', 'perms': {'add': True, 'change': True, 'delete': True}, 'admin_url': '/admin/auth/user/', 'add_url': '/admin/auth/user/add/'}, {'name': '组', 'object_name': 'Group', 'perms': {'add': True, 'change': True, 'delete': True}, 'admin_url': '/admin/auth/group/', 'add_url': '/admin/auth/group/add/'}]}], 'LANGUAGE_CODE': 'zh-hans', 'LANGUAGE_BIDI': False}]"
2018-11-16 18:55:28 [django.server:124] [INFO] - "GET /admin/ HTTP/1.1" 200 6282
2018-11-16 18:55:28 [django.template:925] [DEBUG] - Exception while resolving variable 'is_popup' in template 'admin/index.html'.
Traceback (most recent call last):
  File "/Library/Frameworks/Python.framework/Versions/3.6/lib/python3.6/site-packages/django/template/base.py", line 882, in _resolve_lookup
    current = current[bit]
  File "/Library/Frameworks/Python.framework/Versions/3.6/lib/python3.6/site-packages/django/template/context.py", line 87, in __getitem__
    raise KeyError(key)
KeyError: 'is_popup'

During handling of the above exception, another exception occurred:

Traceback (most recent call last):
  File "/Library/Frameworks/Python.framework/Versions/3.6/lib/python3.6/site-packages/django/template/base.py", line 888, in _resolve_lookup
    if isinstance(current, BaseContext) and getattr(type(current), bit):
AttributeError: type object 'RequestContext' has no attribute 'is_popup'

During handling of the above exception, another exception occurred:

Traceback (most recent call last):
  File "/Library/Frameworks/Python.framework/Versions/3.6/lib/python3.6/site-packages/django/template/base.py", line 896, in _resolve_lookup
    current = current[int(bit)]
ValueError: invalid literal for int() with base 10: 'is_popup'

During handling of the above exception, another exception occurred:

Traceback (most recent call last):
  File "/Library/Frameworks/Python.framework/Versions/3.6/lib/python3.6/site-packages/django/template/base.py", line 903, in _resolve_lookup
    (bit, current))  # missing attribute
django.template.base.VariableDoesNotExist: Failed lookup for key [is_popup] in "[{'True': True, 'False': False, 'None': None}, {'csrf_token': <SimpleLazyObject: <function csrf.<locals>._get_val at 0x10d752598>>, 'request': <WSGIRequest: GET '/admin/'>, 'user': <SimpleLazyObject: <User: root>>, 'perms': <django.contrib.auth.context_processors.PermWrapper object at 0x10ef6a4a8>, 'messages': <django.contrib.messages.storage.fallback.FallbackStorage object at 0x10ef7f7b8>, 'DEFAULT_MESSAGE_LEVELS': {'DEBUG': 10, 'INFO': 20, 'SUCCESS': 25, 'WARNING': 30, 'ERROR': 40}}, {}, {'site_title': 'Django 站点管理员', 'site_header': 'Django 管理', 'site_url': '/', 'has_permission': True, 'available_apps': [{'name': 'User', 'app_label': 'user', 'app_url': '/admin/user/', 'has_module_perms': True, 'models': [{'name': 'Userss', 'object_name': 'Users', 'perms': {'add': True, 'change': True, 'delete': True}, 'admin_url': '/admin/user/users/', 'add_url': '/admin/user/users/add/'}]}, {'name': '认证和授权', 'app_label': 'auth', 'app_url': '/admin/auth/', 'has_module_perms': True, 'models': [{'name': '用户', 'object_name': 'User', 'perms': {'add': True, 'change': True, 'delete': True}, 'admin_url': '/admin/auth/user/', 'add_url': '/admin/auth/user/add/'}, {'name': '组', 'object_name': 'Group', 'perms': {'add': True, 'change': True, 'delete': True}, 'admin_url': '/admin/auth/group/', 'add_url': '/admin/auth/group/add/'}]}], 'title': '站点管理', 'app_list': [{'name': 'User', 'app_label': 'user', 'app_url': '/admin/user/', 'has_module_perms': True, 'models': [{'name': 'Userss', 'object_name': 'Users', 'perms': {'add': True, 'change': True, 'delete': True}, 'admin_url': '/admin/user/users/', 'add_url': '/admin/user/users/add/'}]}, {'name': '认证和授权', 'app_label': 'auth', 'app_url': '/admin/auth/', 'has_module_perms': True, 'models': [{'name': '用户', 'object_name': 'User', 'perms': {'add': True, 'change': True, 'delete': True}, 'admin_url': '/admin/auth/user/', 'add_url': '/admin/auth/user/add/'}, {'name': '组', 'object_name': 'Group', 'perms': {'add': True, 'change': True, 'delete': True}, 'admin_url': '/admin/auth/group/', 'add_url': '/admin/auth/group/add/'}]}], 'LANGUAGE_CODE': 'zh-hans', 'LANGUAGE_BIDI': False}]"
2018-11-16 18:55:28 [django.template:925] [DEBUG] - Exception while resolving variable 'is_popup' in template 'admin/index.html'.
Traceback (most recent call last):
  File "/Library/Frameworks/Python.framework/Versions/3.6/lib/python3.6/site-packages/django/template/base.py", line 882, in _resolve_lookup
    current = current[bit]
  File "/Library/Frameworks/Python.framework/Versions/3.6/lib/python3.6/site-packages/django/template/context.py", line 87, in __getitem__
    raise KeyError(key)
KeyError: 'is_popup'

During handling of the above exception, another exception occurred:

Traceback (most recent call last):
  File "/Library/Frameworks/Python.framework/Versions/3.6/lib/python3.6/site-packages/django/template/base.py", line 888, in _resolve_lookup
    if isinstance(current, BaseContext) and getattr(type(current), bit):
AttributeError: type object 'RequestContext' has no attribute 'is_popup'

During handling of the above exception, another exception occurred:

Traceback (most recent call last):
  File "/Library/Frameworks/Python.framework/Versions/3.6/lib/python3.6/site-packages/django/template/base.py", line 896, in _resolve_lookup
    current = current[int(bit)]
ValueError: invalid literal for int() with base 10: 'is_popup'

During handling of the above exception, another exception occurred:

Traceback (most recent call last):
  File "/Library/Frameworks/Python.framework/Versions/3.6/lib/python3.6/site-packages/django/template/base.py", line 903, in _resolve_lookup
    (bit, current))  # missing attribute
django.template.base.VariableDoesNotExist: Failed lookup for key [is_popup] in "[{'True': True, 'False': False, 'None': None}, {'csrf_token': <SimpleLazyObject: <function csrf.<locals>._get_val at 0x10d752598>>, 'request': <WSGIRequest: GET '/admin/'>, 'user': <SimpleLazyObject: <User: root>>, 'perms': <django.contrib.auth.context_processors.PermWrapper object at 0x10ef6a4a8>, 'messages': <django.contrib.messages.storage.fallback.FallbackStorage object at 0x10ef7f7b8>, 'DEFAULT_MESSAGE_LEVELS': {'DEBUG': 10, 'INFO': 20, 'SUCCESS': 25, 'WARNING': 30, 'ERROR': 40}}, {}, {'site_title': 'Django 站点管理员', 'site_header': 'Django 管理', 'site_url': '/', 'has_permission': True, 'available_apps': [{'name': 'User', 'app_label': 'user', 'app_url': '/admin/user/', 'has_module_perms': True, 'models': [{'name': 'Userss', 'object_name': 'Users', 'perms': {'add': True, 'change': True, 'delete': True}, 'admin_url': '/admin/user/users/', 'add_url': '/admin/user/users/add/'}]}, {'name': '认证和授权', 'app_label': 'auth', 'app_url': '/admin/auth/', 'has_module_perms': True, 'models': [{'name': '用户', 'object_name': 'User', 'perms': {'add': True, 'change': True, 'delete': True}, 'admin_url': '/admin/auth/user/', 'add_url': '/admin/auth/user/add/'}, {'name': '组', 'object_name': 'Group', 'perms': {'add': True, 'change': True, 'delete': True}, 'admin_url': '/admin/auth/group/', 'add_url': '/admin/auth/group/add/'}]}], 'title': '站点管理', 'app_list': [{'name': 'User', 'app_label': 'user', 'app_url': '/admin/user/', 'has_module_perms': True, 'models': [{'name': 'Userss', 'object_name': 'Users', 'perms': {'add': True, 'change': True, 'delete': True}, 'admin_url': '/admin/user/users/', 'add_url': '/admin/user/users/add/'}]}, {'name': '认证和授权', 'app_label': 'auth', 'app_url': '/admin/auth/', 'has_module_perms': True, 'models': [{'name': '用户', 'object_name': 'User', 'perms': {'add': True, 'change': True, 'delete': True}, 'admin_url': '/admin/auth/user/', 'add_url': '/admin/auth/user/add/'}, {'name': '组', 'object_name': 'Group', 'perms': {'add': True, 'change': True, 'delete': True}, 'admin_url': '/admin/auth/group/', 'add_url': '/admin/auth/group/add/'}]}], 'LANGUAGE_CODE': 'zh-hans', 'LANGUAGE_BIDI': False}]"
2018-11-16 18:55:28 [django.server:124] [INFO] - "GET /admin/ HTTP/1.1" 200 6282
2018-11-16 18:55:37 [django.server:124] [INFO] - "GET /user/list HTTP/1.1" 200 9534
2018-11-16 18:55:38 [django.server:124] [WARNING] - "GET /static/fonts/fontawesome-webfont.woff2?v=4.7.0 HTTP/1.1" 404 1714
2018-11-16 18:55:54 [django.server:124] [INFO] - "POST /user/add HTTP/1.1" 302 0
2018-11-16 18:55:54 [django.server:124] [INFO] - "GET /user/list HTTP/1.1" 200 9995
2018-11-16 18:55:54 [django.server:124] [WARNING] - "GET /static/fonts/fontawesome-webfont.woff2?v=4.7.0 HTTP/1.1" 404 1714
2018-11-16 18:56:08 [django.server:124] [INFO] - "POST /user/add HTTP/1.1" 302 0
2018-11-16 18:56:08 [django.server:124] [INFO] - "GET /user/list HTTP/1.1" 200 10457
2018-11-16 18:56:08 [django.server:124] [WARNING] - "GET /static/fonts/fontawesome-webfont.woff2?v=4.7.0 HTTP/1.1" 404 1714
2018-11-16 18:56:22 [django.server:124] [INFO] - "POST /user/add HTTP/1.1" 302 0
2018-11-16 18:56:22 [django.server:124] [INFO] - "GET /user/list HTTP/1.1" 200 10917
2018-11-16 18:56:22 [django.server:124] [WARNING] - "GET /static/fonts/fontawesome-webfont.woff2?v=4.7.0 HTTP/1.1" 404 1714
2018-11-16 18:56:37 [django.server:124] [INFO] - "POST /user/add HTTP/1.1" 302 0
2018-11-16 18:56:37 [django.server:124] [INFO] - "GET /user/list HTTP/1.1" 200 11379
2018-11-16 18:56:37 [django.server:124] [WARNING] - "GET /static/fonts/fontawesome-webfont.woff2?v=4.7.0 HTTP/1.1" 404 1714
2018-11-16 18:56:51 [django.server:124] [INFO] - "POST /user/add HTTP/1.1" 302 0
2018-11-16 18:56:51 [django.server:124] [INFO] - "GET /user/list HTTP/1.1" 200 11841
2018-11-16 18:56:51 [django.server:124] [WARNING] - "GET /static/fonts/fontawesome-webfont.woff2?v=4.7.0 HTTP/1.1" 404 1714
2018-11-16 18:56:53 [django.server:124] [INFO] - "GET /user/detail/?id=29 HTTP/1.1" 200 10223
2018-11-16 18:56:53 [django.server:124] [WARNING] - "GET /static/fonts/fontawesome-webfont.woff2?v=4.7.0 HTTP/1.1" 404 1714
2018-11-16 18:57:00 [django.server:124] [INFO] - "PUT /user/update/29/ HTTP/1.1" 200 32
2018-11-16 18:57:01 [django.server:124] [INFO] - "GET /user/detail/?id=29&username=xiaohong&gender=0&id_card=111111&age=26&address=shanghai&remark=%E4%B8%8A%E6%B5%B7 HTTP/1.1" 200 10223
2018-11-16 18:57:01 [django.server:124] [WARNING] - "GET /static/fonts/fontawesome-webfont.woff2?v=4.7.0 HTTP/1.1" 404 1714
2018-11-16 18:57:05 [django.server:124] [INFO] - "GET /user/detail/?id=29&username=xiaohong&gender=0&id_card=111111&age=26&address=shanghai&remark=%E4%B8%8A%E6%B5%B7 HTTP/1.1" 200 10223
2018-11-16 18:57:05 [django.server:124] [WARNING] - "GET /static/fonts/fontawesome-webfont.woff2?v=4.7.0 HTTP/1.1" 404 1714
2018-11-16 18:57:07 [django.server:124] [INFO] - "GET /user/list HTTP/1.1" 200 11841
2018-11-16 18:57:07 [django.server:124] [WARNING] - "GET /static/fonts/fontawesome-webfont.woff2?v=4.7.0 HTTP/1.1" 404 1714
2018-11-16 18:57:36 [django.server:124] [INFO] - "GET /user/export/ HTTP/1.1" 200 783
