2018-11-17 19:28:20 [django.request:152] [WARNING] - Not Found: /favicon.ico
2018-11-17 19:40:14 [django.request:135] [ERROR] - Internal Server Error: /assets/list/
Traceback (most recent call last):
  File "/home/monkey/python36env/lib/python3.6/site-packages/django/db/backends/utils.py", line 65, in execute
    return self.cursor.execute(sql, params)
  File "/home/monkey/python36env/lib/python3.6/site-packages/django/db/backends/mysql/base.py", line 101, in execute
    return self.cursor.execute(query, args)
  File "/home/monkey/python36env/lib/python3.6/site-packages/pymysql/cursors.py", line 170, in execute
    result = self._query(query)
  File "/home/monkey/python36env/lib/python3.6/site-packages/pymysql/cursors.py", line 328, in _query
    conn.query(q)
  File "/home/monkey/python36env/lib/python3.6/site-packages/pymysql/connections.py", line 893, in query
    self._affected_rows = self._read_query_result(unbuffered=unbuffered)
  File "/home/monkey/python36env/lib/python3.6/site-packages/pymysql/connections.py", line 1103, in _read_query_result
    result.read()
  File "/home/monkey/python36env/lib/python3.6/site-packages/pymysql/connections.py", line 1396, in read
    first_packet = self.connection._read_packet()
  File "/home/monkey/python36env/lib/python3.6/site-packages/pymysql/connections.py", line 1059, in _read_packet
    packet.check_error()
  File "/home/monkey/python36env/lib/python3.6/site-packages/pymysql/connections.py", line 384, in check_error
    err.raise_mysql_exception(self._data)
  File "/home/monkey/python36env/lib/python3.6/site-packages/pymysql/err.py", line 109, in raise_mysql_exception
    raise errorclass(errno, errval)
pymysql.err.ProgrammingError: (1146, "Table 'python19.assets' doesn't exist")

The above exception was the direct cause of the following exception:

Traceback (most recent call last):
  File "/home/monkey/python36env/lib/python3.6/site-packages/django/core/handlers/exception.py", line 41, in inner
    response = get_response(request)
  File "/home/monkey/python36env/lib/python3.6/site-packages/django/core/handlers/base.py", line 187, in _get_response
    response = self.process_exception_by_middleware(e, request)
  File "/home/monkey/python36env/lib/python3.6/site-packages/django/core/handlers/base.py", line 185, in _get_response
    response = wrapped_callback(request, *callback_args, **callback_kwargs)
  File "/home/monkey/python36env/lib/python3.6/site-packages/django/views/decorators/http.py", line 40, in inner
    return func(request, *args, **kwargs)
  File "/home/monkey/python36env/lib/python3.6/site-packages/django/contrib/auth/decorators.py", line 23, in _wrapped_view
    return view_func(request, *args, **kwargs)
  File "/home/monkey/go/src/github.com/51reboot/actual-19-homework/lesson13/zhengyscn/webapp/assets/views.py", line 30, in AssetsListView
    return render(request, "assets.html", context={"content": objs})
  File "/home/monkey/python36env/lib/python3.6/site-packages/django/shortcuts.py", line 30, in render
    content = loader.render_to_string(template_name, context, request, using=using)
  File "/home/monkey/python36env/lib/python3.6/site-packages/django/template/loader.py", line 68, in render_to_string
    return template.render(context, request)
  File "/home/monkey/python36env/lib/python3.6/site-packages/django/template/backends/django.py", line 66, in render
    return self.template.render(context)
  File "/home/monkey/python36env/lib/python3.6/site-packages/django/template/base.py", line 207, in render
    return self._render(context)
  File "/home/monkey/python36env/lib/python3.6/site-packages/django/template/base.py", line 199, in _render
    return self.nodelist.render(context)
  File "/home/monkey/python36env/lib/python3.6/site-packages/django/template/base.py", line 990, in render
    bit = node.render_annotated(context)
  File "/home/monkey/python36env/lib/python3.6/site-packages/django/template/base.py", line 957, in render_annotated
    return self.render(context)
  File "/home/monkey/python36env/lib/python3.6/site-packages/django/template/loader_tags.py", line 177, in render
    return compiled_parent._render(context)
  File "/home/monkey/python36env/lib/python3.6/site-packages/django/template/base.py", line 199, in _render
    return self.nodelist.render(context)
  File "/home/monkey/python36env/lib/python3.6/site-packages/django/template/base.py", line 990, in render
    bit = node.render_annotated(context)
  File "/home/monkey/python36env/lib/python3.6/site-packages/django/template/base.py", line 957, in render_annotated
    return self.render(context)
  File "/home/monkey/python36env/lib/python3.6/site-packages/django/template/loader_tags.py", line 72, in render
    result = block.nodelist.render(context)
  File "/home/monkey/python36env/lib/python3.6/site-packages/django/template/base.py", line 990, in render
    bit = node.render_annotated(context)
  File "/home/monkey/python36env/lib/python3.6/site-packages/django/template/base.py", line 957, in render_annotated
    return self.render(context)
  File "/home/monkey/python36env/lib/python3.6/site-packages/django/template/defaulttags.py", line 173, in render
    len_values = len(values)
  File "/home/monkey/python36env/lib/python3.6/site-packages/django/db/models/query.py", line 232, in __len__
    self._fetch_all()
  File "/home/monkey/python36env/lib/python3.6/site-packages/django/db/models/query.py", line 1105, in _fetch_all
    self._result_cache = list(self._iterable_class(self))
  File "/home/monkey/python36env/lib/python3.6/site-packages/django/db/models/query.py", line 53, in __iter__
    results = compiler.execute_sql(chunked_fetch=self.chunked_fetch)
  File "/home/monkey/python36env/lib/python3.6/site-packages/django/db/models/sql/compiler.py", line 886, in execute_sql
    raise original_exception
  File "/home/monkey/python36env/lib/python3.6/site-packages/django/db/models/sql/compiler.py", line 876, in execute_sql
    cursor.execute(sql, params)
  File "/home/monkey/python36env/lib/python3.6/site-packages/django/db/backends/utils.py", line 80, in execute
    return super(CursorDebugWrapper, self).execute(sql, params)
  File "/home/monkey/python36env/lib/python3.6/site-packages/django/db/backends/utils.py", line 65, in execute
    return self.cursor.execute(sql, params)
  File "/home/monkey/python36env/lib/python3.6/site-packages/django/db/utils.py", line 94, in __exit__
    six.reraise(dj_exc_type, dj_exc_value, traceback)
  File "/home/monkey/python36env/lib/python3.6/site-packages/django/utils/six.py", line 685, in reraise
    raise value.with_traceback(tb)
  File "/home/monkey/python36env/lib/python3.6/site-packages/django/db/backends/utils.py", line 65, in execute
    return self.cursor.execute(sql, params)
  File "/home/monkey/python36env/lib/python3.6/site-packages/django/db/backends/mysql/base.py", line 101, in execute
    return self.cursor.execute(query, args)
  File "/home/monkey/python36env/lib/python3.6/site-packages/pymysql/cursors.py", line 170, in execute
    result = self._query(query)
  File "/home/monkey/python36env/lib/python3.6/site-packages/pymysql/cursors.py", line 328, in _query
    conn.query(q)
  File "/home/monkey/python36env/lib/python3.6/site-packages/pymysql/connections.py", line 893, in query
    self._affected_rows = self._read_query_result(unbuffered=unbuffered)
  File "/home/monkey/python36env/lib/python3.6/site-packages/pymysql/connections.py", line 1103, in _read_query_result
    result.read()
  File "/home/monkey/python36env/lib/python3.6/site-packages/pymysql/connections.py", line 1396, in read
    first_packet = self.connection._read_packet()
  File "/home/monkey/python36env/lib/python3.6/site-packages/pymysql/connections.py", line 1059, in _read_packet
    packet.check_error()
  File "/home/monkey/python36env/lib/python3.6/site-packages/pymysql/connections.py", line 384, in check_error
    err.raise_mysql_exception(self._data)
  File "/home/monkey/python36env/lib/python3.6/site-packages/pymysql/err.py", line 109, in raise_mysql_exception
    raise errorclass(errno, errval)
django.db.utils.ProgrammingError: (1146, "Table 'python19.assets' doesn't exist")
2018-11-17 19:40:16 [django.request:135] [ERROR] - Internal Server Error: /assets/list/
Traceback (most recent call last):
  File "/home/monkey/python36env/lib/python3.6/site-packages/django/db/backends/utils.py", line 65, in execute
    return self.cursor.execute(sql, params)
  File "/home/monkey/python36env/lib/python3.6/site-packages/django/db/backends/mysql/base.py", line 101, in execute
    return self.cursor.execute(query, args)
  File "/home/monkey/python36env/lib/python3.6/site-packages/pymysql/cursors.py", line 170, in execute
    result = self._query(query)
  File "/home/monkey/python36env/lib/python3.6/site-packages/pymysql/cursors.py", line 328, in _query
    conn.query(q)
  File "/home/monkey/python36env/lib/python3.6/site-packages/pymysql/connections.py", line 893, in query
    self._affected_rows = self._read_query_result(unbuffered=unbuffered)
  File "/home/monkey/python36env/lib/python3.6/site-packages/pymysql/connections.py", line 1103, in _read_query_result
    result.read()
  File "/home/monkey/python36env/lib/python3.6/site-packages/pymysql/connections.py", line 1396, in read
    first_packet = self.connection._read_packet()
  File "/home/monkey/python36env/lib/python3.6/site-packages/pymysql/connections.py", line 1059, in _read_packet
    packet.check_error()
  File "/home/monkey/python36env/lib/python3.6/site-packages/pymysql/connections.py", line 384, in check_error
    err.raise_mysql_exception(self._data)
  File "/home/monkey/python36env/lib/python3.6/site-packages/pymysql/err.py", line 109, in raise_mysql_exception
    raise errorclass(errno, errval)
pymysql.err.ProgrammingError: (1146, "Table 'python19.assets' doesn't exist")

The above exception was the direct cause of the following exception:

Traceback (most recent call last):
  File "/home/monkey/python36env/lib/python3.6/site-packages/django/core/handlers/exception.py", line 41, in inner
    response = get_response(request)
  File "/home/monkey/python36env/lib/python3.6/site-packages/django/core/handlers/base.py", line 187, in _get_response
    response = self.process_exception_by_middleware(e, request)
  File "/home/monkey/python36env/lib/python3.6/site-packages/django/core/handlers/base.py", line 185, in _get_response
    response = wrapped_callback(request, *callback_args, **callback_kwargs)
  File "/home/monkey/python36env/lib/python3.6/site-packages/django/views/decorators/http.py", line 40, in inner
    return func(request, *args, **kwargs)
  File "/home/monkey/python36env/lib/python3.6/site-packages/django/contrib/auth/decorators.py", line 23, in _wrapped_view
    return view_func(request, *args, **kwargs)
  File "/home/monkey/go/src/github.com/51reboot/actual-19-homework/lesson13/zhengyscn/webapp/assets/views.py", line 30, in AssetsListView
    return render(request, "assets.html", context={"content": objs})
  File "/home/monkey/python36env/lib/python3.6/site-packages/django/shortcuts.py", line 30, in render
    content = loader.render_to_string(template_name, context, request, using=using)
  File "/home/monkey/python36env/lib/python3.6/site-packages/django/template/loader.py", line 68, in render_to_string
    return template.render(context, request)
  File "/home/monkey/python36env/lib/python3.6/site-packages/django/template/backends/django.py", line 66, in render
    return self.template.render(context)
  File "/home/monkey/python36env/lib/python3.6/site-packages/django/template/base.py", line 207, in render
    return self._render(context)
  File "/home/monkey/python36env/lib/python3.6/site-packages/django/template/base.py", line 199, in _render
    return self.nodelist.render(context)
  File "/home/monkey/python36env/lib/python3.6/site-packages/django/template/base.py", line 990, in render
    bit = node.render_annotated(context)
  File "/home/monkey/python36env/lib/python3.6/site-packages/django/template/base.py", line 957, in render_annotated
    return self.render(context)
  File "/home/monkey/python36env/lib/python3.6/site-packages/django/template/loader_tags.py", line 177, in render
    return compiled_parent._render(context)
  File "/home/monkey/python36env/lib/python3.6/site-packages/django/template/base.py", line 199, in _render
    return self.nodelist.render(context)
  File "/home/monkey/python36env/lib/python3.6/site-packages/django/template/base.py", line 990, in render
    bit = node.render_annotated(context)
  File "/home/monkey/python36env/lib/python3.6/site-packages/django/template/base.py", line 957, in render_annotated
    return self.render(context)
  File "/home/monkey/python36env/lib/python3.6/site-packages/django/template/loader_tags.py", line 72, in render
    result = block.nodelist.render(context)
  File "/home/monkey/python36env/lib/python3.6/site-packages/django/template/base.py", line 990, in render
    bit = node.render_annotated(context)
  File "/home/monkey/python36env/lib/python3.6/site-packages/django/template/base.py", line 957, in render_annotated
    return self.render(context)
  File "/home/monkey/python36env/lib/python3.6/site-packages/django/template/defaulttags.py", line 173, in render
    len_values = len(values)
  File "/home/monkey/python36env/lib/python3.6/site-packages/django/db/models/query.py", line 232, in __len__
    self._fetch_all()
  File "/home/monkey/python36env/lib/python3.6/site-packages/django/db/models/query.py", line 1105, in _fetch_all
    self._result_cache = list(self._iterable_class(self))
  File "/home/monkey/python36env/lib/python3.6/site-packages/django/db/models/query.py", line 53, in __iter__
    results = compiler.execute_sql(chunked_fetch=self.chunked_fetch)
  File "/home/monkey/python36env/lib/python3.6/site-packages/django/db/models/sql/compiler.py", line 886, in execute_sql
    raise original_exception
  File "/home/monkey/python36env/lib/python3.6/site-packages/django/db/models/sql/compiler.py", line 876, in execute_sql
    cursor.execute(sql, params)
  File "/home/monkey/python36env/lib/python3.6/site-packages/django/db/backends/utils.py", line 80, in execute
    return super(CursorDebugWrapper, self).execute(sql, params)
  File "/home/monkey/python36env/lib/python3.6/site-packages/django/db/backends/utils.py", line 65, in execute
    return self.cursor.execute(sql, params)
  File "/home/monkey/python36env/lib/python3.6/site-packages/django/db/utils.py", line 94, in __exit__
    six.reraise(dj_exc_type, dj_exc_value, traceback)
  File "/home/monkey/python36env/lib/python3.6/site-packages/django/utils/six.py", line 685, in reraise
    raise value.with_traceback(tb)
  File "/home/monkey/python36env/lib/python3.6/site-packages/django/db/backends/utils.py", line 65, in execute
    return self.cursor.execute(sql, params)
  File "/home/monkey/python36env/lib/python3.6/site-packages/django/db/backends/mysql/base.py", line 101, in execute
    return self.cursor.execute(query, args)
  File "/home/monkey/python36env/lib/python3.6/site-packages/pymysql/cursors.py", line 170, in execute
    result = self._query(query)
  File "/home/monkey/python36env/lib/python3.6/site-packages/pymysql/cursors.py", line 328, in _query
    conn.query(q)
  File "/home/monkey/python36env/lib/python3.6/site-packages/pymysql/connections.py", line 893, in query
    self._affected_rows = self._read_query_result(unbuffered=unbuffered)
  File "/home/monkey/python36env/lib/python3.6/site-packages/pymysql/connections.py", line 1103, in _read_query_result
    result.read()
  File "/home/monkey/python36env/lib/python3.6/site-packages/pymysql/connections.py", line 1396, in read
    first_packet = self.connection._read_packet()
  File "/home/monkey/python36env/lib/python3.6/site-packages/pymysql/connections.py", line 1059, in _read_packet
    packet.check_error()
  File "/home/monkey/python36env/lib/python3.6/site-packages/pymysql/connections.py", line 384, in check_error
    err.raise_mysql_exception(self._data)
  File "/home/monkey/python36env/lib/python3.6/site-packages/pymysql/err.py", line 109, in raise_mysql_exception
    raise errorclass(errno, errval)
django.db.utils.ProgrammingError: (1146, "Table 'python19.assets' doesn't exist")
2018-11-17 20:37:35 [django.request:135] [ERROR] - Internal Server Error: /user/list/
Traceback (most recent call last):
  File "/home/monkey/python36env/lib/python3.6/site-packages/django/db/backends/utils.py", line 65, in execute
    return self.cursor.execute(sql, params)
  File "/home/monkey/python36env/lib/python3.6/site-packages/django/db/backends/mysql/base.py", line 101, in execute
    return self.cursor.execute(query, args)
  File "/home/monkey/python36env/lib/python3.6/site-packages/pymysql/cursors.py", line 170, in execute
    result = self._query(query)
  File "/home/monkey/python36env/lib/python3.6/site-packages/pymysql/cursors.py", line 328, in _query
    conn.query(q)
  File "/home/monkey/python36env/lib/python3.6/site-packages/pymysql/connections.py", line 893, in query
    self._affected_rows = self._read_query_result(unbuffered=unbuffered)
  File "/home/monkey/python36env/lib/python3.6/site-packages/pymysql/connections.py", line 1103, in _read_query_result
    result.read()
  File "/home/monkey/python36env/lib/python3.6/site-packages/pymysql/connections.py", line 1396, in read
    first_packet = self.connection._read_packet()
  File "/home/monkey/python36env/lib/python3.6/site-packages/pymysql/connections.py", line 1059, in _read_packet
    packet.check_error()
  File "/home/monkey/python36env/lib/python3.6/site-packages/pymysql/connections.py", line 384, in check_error
    err.raise_mysql_exception(self._data)
  File "/home/monkey/python36env/lib/python3.6/site-packages/pymysql/err.py", line 109, in raise_mysql_exception
    raise errorclass(errno, errval)
pymysql.err.ProgrammingError: (1146, "Table 'python191.users' doesn't exist")

The above exception was the direct cause of the following exception:

Traceback (most recent call last):
  File "/home/monkey/python36env/lib/python3.6/site-packages/django/core/handlers/exception.py", line 41, in inner
    response = get_response(request)
  File "/home/monkey/python36env/lib/python3.6/site-packages/django/core/handlers/base.py", line 187, in _get_response
    response = self.process_exception_by_middleware(e, request)
  File "/home/monkey/python36env/lib/python3.6/site-packages/django/core/handlers/base.py", line 185, in _get_response
    response = wrapped_callback(request, *callback_args, **callback_kwargs)
  File "/home/monkey/python36env/lib/python3.6/site-packages/django/views/decorators/http.py", line 40, in inner
    return func(request, *args, **kwargs)
  File "/home/monkey/python36env/lib/python3.6/site-packages/django/contrib/auth/decorators.py", line 23, in _wrapped_view
    return view_func(request, *args, **kwargs)
  File "/home/monkey/go/src/github.com/51reboot/actual-19-homework/lesson13/zhengyscn/webapp/user/views.py", line 22, in UserListView
    return render(request, "user.html", context={"content" : objs})
  File "/home/monkey/python36env/lib/python3.6/site-packages/django/shortcuts.py", line 30, in render
    content = loader.render_to_string(template_name, context, request, using=using)
  File "/home/monkey/python36env/lib/python3.6/site-packages/django/template/loader.py", line 68, in render_to_string
    return template.render(context, request)
  File "/home/monkey/python36env/lib/python3.6/site-packages/django/template/backends/django.py", line 66, in render
    return self.template.render(context)
  File "/home/monkey/python36env/lib/python3.6/site-packages/django/template/base.py", line 207, in render
    return self._render(context)
  File "/home/monkey/python36env/lib/python3.6/site-packages/django/template/base.py", line 199, in _render
    return self.nodelist.render(context)
  File "/home/monkey/python36env/lib/python3.6/site-packages/django/template/base.py", line 990, in render
    bit = node.render_annotated(context)
  File "/home/monkey/python36env/lib/python3.6/site-packages/django/template/base.py", line 957, in render_annotated
    return self.render(context)
  File "/home/monkey/python36env/lib/python3.6/site-packages/django/template/defaulttags.py", line 173, in render
    len_values = len(values)
  File "/home/monkey/python36env/lib/python3.6/site-packages/django/db/models/query.py", line 232, in __len__
    self._fetch_all()
  File "/home/monkey/python36env/lib/python3.6/site-packages/django/db/models/query.py", line 1105, in _fetch_all
    self._result_cache = list(self._iterable_class(self))
  File "/home/monkey/python36env/lib/python3.6/site-packages/django/db/models/query.py", line 53, in __iter__
    results = compiler.execute_sql(chunked_fetch=self.chunked_fetch)
  File "/home/monkey/python36env/lib/python3.6/site-packages/django/db/models/sql/compiler.py", line 886, in execute_sql
    raise original_exception
  File "/home/monkey/python36env/lib/python3.6/site-packages/django/db/models/sql/compiler.py", line 876, in execute_sql
    cursor.execute(sql, params)
  File "/home/monkey/python36env/lib/python3.6/site-packages/django/db/backends/utils.py", line 80, in execute
    return super(CursorDebugWrapper, self).execute(sql, params)
  File "/home/monkey/python36env/lib/python3.6/site-packages/django/db/backends/utils.py", line 65, in execute
    return self.cursor.execute(sql, params)
  File "/home/monkey/python36env/lib/python3.6/site-packages/django/db/utils.py", line 94, in __exit__
    six.reraise(dj_exc_type, dj_exc_value, traceback)
  File "/home/monkey/python36env/lib/python3.6/site-packages/django/utils/six.py", line 685, in reraise
    raise value.with_traceback(tb)
  File "/home/monkey/python36env/lib/python3.6/site-packages/django/db/backends/utils.py", line 65, in execute
    return self.cursor.execute(sql, params)
  File "/home/monkey/python36env/lib/python3.6/site-packages/django/db/backends/mysql/base.py", line 101, in execute
    return self.cursor.execute(query, args)
  File "/home/monkey/python36env/lib/python3.6/site-packages/pymysql/cursors.py", line 170, in execute
    result = self._query(query)
  File "/home/monkey/python36env/lib/python3.6/site-packages/pymysql/cursors.py", line 328, in _query
    conn.query(q)
  File "/home/monkey/python36env/lib/python3.6/site-packages/pymysql/connections.py", line 893, in query
    self._affected_rows = self._read_query_result(unbuffered=unbuffered)
  File "/home/monkey/python36env/lib/python3.6/site-packages/pymysql/connections.py", line 1103, in _read_query_result
    result.read()
  File "/home/monkey/python36env/lib/python3.6/site-packages/pymysql/connections.py", line 1396, in read
    first_packet = self.connection._read_packet()
  File "/home/monkey/python36env/lib/python3.6/site-packages/pymysql/connections.py", line 1059, in _read_packet
    packet.check_error()
  File "/home/monkey/python36env/lib/python3.6/site-packages/pymysql/connections.py", line 384, in check_error
    err.raise_mysql_exception(self._data)
  File "/home/monkey/python36env/lib/python3.6/site-packages/pymysql/err.py", line 109, in raise_mysql_exception
    raise errorclass(errno, errval)
django.db.utils.ProgrammingError: (1146, "Table 'python191.users' doesn't exist")
